Workbook

Sheet AREAS
A1: AREA 1 | B1: ARERA 2 | C1: AREA 3 | D1: AREA 4 | E1: PRODUCTOS | F1: PRESENTACION | G1: GRAMAJE | H1: UNIDADES
A2: PIZZA | B2: COCINA | C2: PARRILLA | E2: DESMECHADA | F2: GRAMAJE | G2: GRAMAJE
A3: PIZZA | B3: COCINA | E3: JAMON | F3: PAQUETE | G3: 500 GM
A4: PIZZA | B4: COCINA | E4: QUESO PIZZA | F4: BLOQUE | G4: 2500 GM
A5: PIZZA | B5: COCINA | E5: CHAMPIÑONES | F5: PAQUETE | G5: 250 GM
A6: PIZZA | B6: COCINA | E6: SALCHICHA IDEAL | F6: PAQUETE | G6: 610 GM | H6: 10
A7: PIZZA | B7: COCINA | E7: POLLO PIZZA | F7: GRAMAJE
A8: PIZZA | B8: COCINA | E8: CARNE PIZZA | F8: GRAMAJE
B9: COCINA | E9: CHISS TREES | F9: PAQUETE | H9: 24
A10: PIZZA | B10: COCINA | C10: PARRILLA | E10: MAZORCA | F10: KILO | G10: 1000 GM
A11: PIZZA | B11: COCINA | E11: SALCHICHA RANCHERA | F11: PAQUETE | G11: 460 GM
A12: PIZZA | B12: COCINA | E12: SALCHICHON | F12: BARRA | G12: 1200 GM
B13: COCINA | C13: PARRILLA | E13: PAN HAMBURGUESA | F13: PAQUETE | H13: 10 UNIDADES
B14: COCINA | C14: PARRILLA | E14: CARNE HAMBURGUESA | H14: UNIDAD
B15: COCINA | C15: PARRILLA | E15: POLLO HAMBURGUESA | F15: CAJA | H15: 24 UNIDADES
B16: COCINA | C16: PARRILLA | E16: PAN PERRO | F16: PAQUETE | H16: 6 UNIDADES
B17: COCINA | C17: PARRILLA | E17: SALCHICHA AMERICANA | F17: PAQUETE | H17: 18 UNIDADES
B18: COCINA | C18: PARRILLA | E18: SALCHICHA SUIZA | F18: PAQUETE | H18: 8 UNIDADES
B19: COCINA | C19: PARRILLA | E19: PAPA FRANCESA | F19: PAQUETE | G19: 2500 GRAMOS
B20: COCINA | C20: PARRILLA | E20: CHORIZOS | F20: PAQUETE | H20: 10 UNIDADES
B21: COCINA | E21: COSTILLITAS | F21: PAQUETE | H21: 1 UNIDAD
B22: COCINA | E22: CHURRASCOS | H22: UNIDAD
B23: COCINA | E23: PECHUGA | H23: UNIDAD
D24: NEVERA | E24: GASEOSA 350 | H24: UNIDAD
D25: NEVERA | E25: JUGO HIT 500 | H25: UNIDAD
D26: NEVERA | E26: GASEOSA 400 | H26: UNIDAD
D27: NEVERA | E27: GASEOSA 500 | H27: UNIDAD
D28: NEVERA | E28: GASEOSA 1.5 | H28: UNIDAD
B29: COCINA | E29: MAZORCADA | H29: UNIDAD
D30: NEVERA | E30: GATORADE | H30: UNIDAD
D31: NEVERA | E31: GASEOSA 3.0 | H31: UNIDAD
D32: NEVERA | E32: TEE | H32: UNIDAD
D33: NEVERA | E33: CERVEZA POKER | H33: UNIDAD
D34: NEVERA | E34: AGUA CON GAS | H34: UNIDAD
D35: NEVERA | E35: AGUA SIN GAS | H35: UNIDAD
B36: COCINA | E36: PICADAS | H36: UNIDAD
D37: NEVERA | E37: SAVILOE 420 | H37: UNIDAD
B38: COCINA | C38: PARRILLA | E38: CHORIZO CUNCIA | H38: UNIDAD
D39: NEVERA | E39: CORONA | H39: UNIDAD
D40: NEVERA | E40: SPEED | H40: UNIDAD
...

Sheet Gastos_JC
A1: Fecha | B1: Producto | C1: Cantidad | D1: Autorizado_Por | E1: Motivo

Sheet Inventario
A1: Fecha | B1: Turno | C1: Área | D1: Producto | E1: Total
A2: 46206 | B2: CIERRE | C2: COCINA | D2: DESMECHADA | E2: 2705 | F2: 46206.611
A3: 46206 | B3: CIERRE | C3: COCINA | D3: JAMON | E3: 2661 | F3: 46206.611
A4: 46206 | B4: CIERRE | C4: COCINA | D4: QUESO PIZZA | E4: 7430 | F4: 46206.611
A5: 46206 | B5: CIERRE | C5: COCINA | D5: CHAMPIÑONES | E5: 1780 | F5: 46206.611
A6: 46206 | B6: CIERRE | C6: COCINA | D6: SALCHICHA IDEAL | E6: 79910 | F6: 46206.611
A7: 46206 | B7: CIERRE | C7: COCINA | D7: POLLO PIZZA | E7: 3215 | F7: 46206.611
A8: 46206 | B8: CIERRE | C8: COCINA | D8: CARNE PIZZA | E8: 5870 | F8: 46206.611
A9: 46206 | B9: CIERRE | C9: COCINA | D9: MAZORCA | E9: 8480 | F9: 46206.611
A10: 46206 | B10: CIERRE | C10: COCINA | D10: SALCHICHA RANCHERA | E10: 1740 | F10: 46206.611
A11: 46206 | B11: CIERRE | C11: COCINA | D11: SALCHICHON | E11: 145 | F11: 46206.611
A12: 46206 | B12: CIERRE | C12: COCINA | D12: PAN HAMBURGUESA | E12: 32 | F12: 46206.611
A13: 46206 | B13: CIERRE | C13: COCINA | D13: CARNE HAMBURGUESA | E13: 47 | F13: 46206.611
... A93: 46207 | B93: CIERRE | C93: COCINA | D93: MINI CHURRASCO | E93: 5 | F93: 46207.644

Sheet Ingresos
A1: Fecha | B1: Turno | C1: Area | D1: Producto | E1: Total
A2: 46207 | B2: JAMON | C2: 2500 | D2: gm | E2: 46207.644
A3: 46207 | B3: QUESO PIZZA | C3: 15000 | D3: gm | E3: 46208.644
A4: 46207 | B4: SALCHICHA IDEAL | C4: 2440 | D4: gm | E4: 46209.644
A5: 46207 | B5: SALCHICHA RANCHERA | C5: 1840 | D5: gm | E5: 46210.644
A6: 46207 | B6: PAN HAMBURGUESA | C6: 60 | D6: und | E6: 46211.644
A7: 46207 | B7: PAN PERRO | C7: 12 | D7: und | E7: 46212.644
A8: 46207 | B8: SALCHICHA AMERICANA | C8: 36 | D8: und | E8: 46213.644
A9: 46207 | B9: PAPA FRANCESA | C9: 10000 | D9: gm | E9: 46214.644
A10: 46207 | B10: COSTILLITAS | C10: 9 | D10: und | E10: 46215.644
A11: 46207 | B11: GASEOSA 350 | C11: 24 | D11: und | E11: 46216.644
A12: 46207 | B12: AGUA SIN GAS | C12: 24 | D12: und | E12: 46217.644
A13: 46207 | B13: PICADAS | C13: 36 | D13: und | E13: 46218.644
... A15: 46207 | B15: QUESO TAJADO | C15: 2400 | D15: gm | E15: 46220.644

Sheet Log_Envios
A1: FechaHora | B1: Filas | C1: Estado
A2: env_1783381314915_w3lgh8 | B2: 46209.779 | C2: 3 | D2: OK
A3: env_1783381879150_zpgud5 | B3: 46209.786 | C3: 3 | D3: OK
A4: env_1783439247995_9bbc40 | B4: 46210.45 | C4: 9 | D4: OK
A5: env_1783625977168 | B5: inventario | C5: 46212.611
A6: env_1783627322951 | B6: ventas | C6: 46212.626
A7: env_1783628841043 | B7: ingreso | C7: 46212.644
A8: env_1783628856828 | B8: inventario | C8: 46212.644

Sheet Reporte
O1: FECHA
A2: PRECIO | B2: CODIGO | C2: PRODUCTO | D2: CANT | E2: VALOR | F2: INSUMO | G2: GASTO | H2: INV_AYER | I2: INGRESO | J2: GASTO J/C | K2: DEBE HABER | L2: EXIS_REAL | M2: FALTO/SOBRO | O2: 46207 | Q2: Resumen Reporte
A3: =VLOOKUP(B3,Productos!$A$2:$D$84,4,0) -> 9000 | B3: 2 | C3: PIZZA HAWALLANA | E3: =D3*A3 -> 0 | F3: DESMECHADA | G3: =(D31*100)+(D10*50)+D58*250 -> 0 | J3: 2 | K3: PIZZA HAWALLANA | L3: I002 | M3: 14 | N3: =VLOOKUP(L3,Insumos!$A$2:$C$67,2) -> JAMON | Q3: ✅ Total vendido
A4: =VLOOKUP(B4,Productos!$A$2:$D$84,4,0) -> 9000 | B4: 3 | C4: PIZZA CHAMPIÑONES | E4: =D4*A4 -> 0 | F4: JAMON | G4: =(D3*14)+(D4*14)+(D5*14)+(D5*14)+(D7*14)+(D8*14)+(D9*14)+(D10*14)+(D11*14)+(D16*18.75)+(D17*37.5)+(D20*37.5)+(D29*56.25)+(D6*14) -> 14 | J4: 2 | K4: PIZZA HAWALLANA | L4: I003 | M4: 80 | N4: =VLOOKUP(L4,Insumos!$A$2:$C$67,2) -> QUESO PIZZA | Q4: ✅ Número de ventas
A5: =VLOOKUP(B5,Productos!$A$2:$D$84,4,0) -> 9000 | B5: 4 | C5: PIZZA CARNES | E5: =D5*A5 -> 0 | F5: QUESO PIZZA | G5: =SUM(D3:D11)*80+(D54*150)+(D84*150) -> 80 | J5: 2 | K5: PIZZA HAWALLANA | L5: I058 | M5: 1 | N5: =VLOOKUP(L5,Insumos!$A$2:$C$67,2) -> MASAS HECHAS | Q5: ✅ Producto más vendido
A6: =VLOOKUP(B6,Productos!$A$2:$D$84,4,0) -> 9000 | B6: 5 | C6: PIZZA MEXICANA | E6: =D6*A6 -> 0 | F6: CHAMPIÑONES | G6: =D4*31.25 -> 0 | J6: 3 | K6: PIZZA CHAMPIÑONES | L6: I002 | M6: 14 | N6: =VLOOKUP(L6,Insumos!$A$2:$C$67,2) -> JAMON | Q6: ✅ Sobra / Falta
A7: =VLOOKUP(B7,Productos!$A$2:$D$84,4,0) -> 9000 | B7: 6 | C7: PIZZA RANCHERA | E7: =D7*A7 -> 0 | F7: SALCHICHA IDEAL | G7: =(D5*31)+(D8*31) -> 31 | J7: 3 | K7: PIZZA CHAMPIÑONES | L7: I003 | M7: 80 | N7: =VLOOKUP(L7,Insumos!$A$2:$C$67,2) -> QUESO PIZZA | Q7: ✅ Gráfico automático
A8: =VLOOKUP(B8,Productos!$A$2:$D$84,4,0) -> 9000 | B8: 7 | C8: PIZZA PERRO | D8: 1 | E8: =D8*A8 -> 9000 | F8: POLLO PIZZA | G8: =(D4*40)+(D5*40) -> 0 | J8: 3 | K8: PIZZA CHAMPIÑONES | L8: I058 | M8: 1 | N8: =VLOOKUP(L8,Insumos!$A$2:$C$67,2) -> MASAS HECHAS
A9: =VLOOKUP(B9,Productos!$A$2:$D$84,4,0) -> 9000 | B9: 8 | C9: PIZZA COLOMBIANA | E9: =D9*A9 -> 0 | F9: CARNE PIZZA | G9: =(D6*63) -> 0 | J9: 3 | K9: PIZZA CHAMPIÑONES | L9: I006 | M9: 40 | N9: =VLOOKUP(L9,Insumos!$A$2:$C$67,2) -> POLLO PIZZA
A10: =VLOOKUP(B10,Productos!$A$2:$D$84,4,0) -> 9000 | B10: 9 | C10: PIZZA DE LA CASA | E10: =D10*A10 -> 0 | F10: CHISS TREES | G10: =(D6/4) -> 0 | J10: 4 | K10: PIZZA CARNES | L10: I002 | M10: 28 | N10: =VLOOKUP(L10,Insumos!$A$2:$C$67,2) -> JAMON
A11: =VLOOKUP(B11,Productos!$A$2:$D$84,4,0) -> 9000 | B11: 10 | C11: PIZZA PEPERONI | E11: =D11*A11 -> 0 | F11: MAZORCA | G11: =(D7*31) -> 0 | J11: 4 | K11: PIZZA CARNES | L11: I003 | M11: 80 | N11: =VLOOKUP(L11,Insumos!$A$2:$C$67,2) -> QUESO PIZZA
A12: =VLOOKUP(B12,Productos!$A$2:$D$84,4,0) -> 14000 | B12: 11 | C12: HAMB. SENCILLA | E12: =D12*A12 -> 0 | F12: SALCHICHA RANCHERA | G12: =(D7*31) -> 0 | J12: 4 | K12: PIZZA CARNES | L12: I005 | M12: 31 | N12: =VLOOKUP(L12,Insumos!$A$2:$C$67,2) -> SALCHICHA IDEAL
A13: =VLOOKUP(B13,Productos!$A$2:$D$84,4,0) -> 16000 | B13: 12 | C13: HAMB. POLLO | E13: =D13*A13 -> 0 | F13: SALCHICHON | J13: 4 | K13: PIZZA CARNES | L13: I006 | M13: 40 | N13: =VLOOKUP(L13,Insumos!$A$2:$C$67,2) -> POLLO PIZZA
A14: =VLOOKUP(B14,Productos!$A$2:$D$84,4,0) -> 19000 | B14: 13 | C14: HAMB. DOBLE CARNE | E14: =D14*A14 -> 0 | F14: PAN HAMBURGUESA | J14: 4 | K14: PIZZA CARNES | L14: I058 | M14: 1 | N14: =VLOOKUP(L14,Insumos!$A$2:$C$67,2) -> MASAS HECHAS
A15: =VLOOKUP(B15,Productos!$A$2:$D$84,4,0) -> 22000 | B15: 14 | C15: HAMB. MIXTA | E15: =D15*A15 -> 0 | F15: CARNE HAMBURGUESA | J15: 5 | K15: PIZZA MEXICANA | L15: I003 | M15: 80 | N15: =VLOOKUP(L15,Insumos!$A$2:$C$67,2) -> QUESO PIZZA
A16: =VLOOKUP(B16,Productos!$A$2:$D$84,4,0) -> 13000 | B16: 15 | C16: PERRO SENCILLO | E16: =D16*A16 -> 0 | F16: POLLO HAMBURGUESA | J16: 5 | K16: PIZZA MEXICANA | L16: I007 | M16: 63 | N16: =VLOOKUP(L16,Insumos!$A$2:$C$67,2) -> CARNE PIZZA
A17: =VLOOKUP(B17,Productos!$A$2:$D$84,4,0) -> 19000 | B17: 16 | C17: PERRO ESPECIAL | E17: =D17*A17 -> 0 | F17: PAN PERRO | J17: 5 | K17: PIZZA MEXICANA | L17: I008 | M17: 0.25 | N17: =VLOOKUP(L17,Insumos!$A$2:$C$67,2) -> CHISS TREES
A18: =VLOOKUP(B18,Productos!$A$2:$D$84,4,0) -> 18000 | B18: 17 | C18: CHORIPERRO | E18: =D18*A18 -> 0 | F18: SALCHICHA AMERICANA | J18: 5 | K18: PIZZA MEXICANA | L18: I058 | M18: 1 | N18: =VLOOKUP(L18,Insumos!$A$2:$C$67,2) -> MASAS HECHAS
A19: =VLOOKUP(B19,Productos!$A$2:$D$84,4,0) -> 16000 | B19: 18 | C19: SALCHIPAPA | E19: =D19*A19 -> 0 | F19: SALCHICHA SUIZA | J19: 6 | K19: PIZZA RANCHERA | L19: I002 | M19: 14 | N19: =VLOOKUP(L19,Insumos!$A$2:$C$67,2) -> JAMON
A20: =VLOOKUP(B20,Productos!$A$2:$D$84,4,0) -> 19000 | B20: 19 | C20: CHORIPAPA | E20: =D20*A20 -> 0 | F20: PAPA FRANCESA | J20: 6 | K20: PIZZA RANCHERA | L20: I003 | M20: 80 | N20: =VLOOKUP(L20,Insumos!$A$2:$C$67,2) -> QUESO PIZZA
A21: =VLOOKUP(B21,Productos!$A$2:$D$84,4,0) -> 21000 | B21: 20 | C21: SUIZA | E21: =D21*A21 -> 0 | F21: CHORIZOS | J21: 6 | K21: PIZZA RANCHERA | L21: I009 | M21: 31 | N21: =VLOOKUP(L21,Insumos!$A$2:$C$67,2) -> MAZORCA
A22: =VLOOKUP(B22,Productos!$A$2:$D$84,4,0) -> 5000 | B22: 21 | C22: PORCION PAPA | E22: =D22*A22 -> 0 | F22: COSTILLITAS | J22: 6 | K22: PIZZA RANCHERA | L22: I010 | M22: 31 | N22: =VLOOKUP(L22,Insumos!$A$2:$C$67,2) -> SALCHICHA RANCHERA
A23: =VLOOKUP(B23,Productos!$A$2:$D$84,4,0) -> 31000 | B23: 22 | C23: COSTILLITAS BBQ | E23: =D23*A23 -> 0 | F23: CHURRASCOS | J23: 6 | K23: PIZZA RANCHERA | L23: I058 | M23: 1 | N23: =VLOOKUP(L23,Insumos!$A$2:$C$67,2) -> MASAS HECHAS
A24: =VLOOKUP(B24,Productos!$A$2:$D$84,4,0) -> 40000 | B24: 23 | C24: CHURRASCO | E24: =D24*A24 -> 0 | F24: PECHUGA | J24: 7 | K24: PIZZA PERRO | L24: I002 | M24: 14 | N24: =VLOOKUP(L24,Insumos!$A$2:$C$67,2) -> JAMON
... A36: =VLOOKUP(B36,Productos!$A$2:$D$84,4,0) -> 12000 | B36: 35 | C36: GASEOSA 3.0 | E36: =D36*A36 -> 0 | F36: AGUA SIN GAS | J36: 9 | K36: PIZZA DE LA CASA | L36: I058 | M36: 1 | N36: =VLOOKUP(L36,Insumos!$A$2:$C$67,2) -> MASAS HECHAS
A37: =VLOOKUP(B37,Productos!$A$2:$D$84,4,0) -> 3000 | B37: 36 | C37: TEE | E37: =D37*A37 -> 0 | F37: PICADAS | J37: 9 | K37: PIZZA DE LA CASA | L37: I001 | M37: 50
A38: =VLOOKUP(B38,Productos!$A$2:$D$84,4,0) -> 4500 | B38: 37 | C38: CERVEZA POKER | E38: =D38*A38 -> 0 | F38: SAVILOE 420 | J38: 10 | K38: PIZZA PEPERONI | L38: I002 | M38: 14 | N38: =VLOOKUP(L38,Insumos!$A$2:$C$67,2) -> JAMON
A39: =VLOOKUP(B39,Productos!$A$2:$D$84,4,0) -> 3500 | B39: 38 | C39: AGUA CON GAS | E39: =D39*A39 -> 0 | F39: CHORIZO CUNCIA | J39: 10 | K39: PIZZA PEPERONI | L39: I003 | M39: 80 | N39: =VLOOKUP(L39,Insumos!$A$2:$C$67,2) -> QUESO PIZZA
A40: =VLOOKUP(B40,Productos!$A$2:$D$84,4,0) -> 3000 | B40: 39 | C40: AGUA SIN GAS | E40: =D40*A40 -> 0 | F40: CORONA | J40: 10 | K40: PIZZA PEPERONI | L40: I058 | M40: 1 | N40: =VLOOKUP(L40,Insumos!$A$2:$C$67,2) -> MASAS HECHAS
A41: =VLOOKUP(B41,Productos!$A$2:$D$84,4,0) -> 4000 | B41: 40 | C41: PATACONA | E41: =D41*A41 -> 0 | F41: SPEED | J41: 10 | K41: PIZZA PEPERONI | L41: I052 | M41: 30 | N41: =VLOOKUP(L41,Insumos!$A$2:$C$67,2) -> PEPEREONY
A42: =VLOOKUP(B42,Productos!$A$2:$D$84,4,0) -> 9000 | B42: 41 | C42: JUGO HIT 1.5 | E42: =D42*A42 -> 0 | F42: MALTA 1.5 | J42: 11 | K42: HAMB. SENCILLA | L42: I012 | M42: 1 | N42: =VLOOKUP(L42,Insumos!$A$2:$C$67,2) -> PAN HAMBURGUESA
A43: =VLOOKUP(B43,Productos!$A$2:$D$84,4,0) -> 9000 | B43: 42 | C43: COLA Y POLA | E43: =D43*A43 -> 0 | F43: CORONITA | J43: 11 | K43: HAMB. SENCILLA | L43: I013 | M43: 1 | N43: =VLOOKUP(L43,Insumos!$A$2:$C$67,2) -> CARNE HAMBURGUESA
A44: =VLOOKUP(B44,Productos!$A$2:$D$84,4,0) -> 8000 | B44: 43 | C44: CORONA | E44: =D44*A44 -> 0 | F44: BRETAÑA | J44: 11 | K44: HAMB. SENCILLA | L44: I051 | M44: 25 | N44: =VLOOKUP(L44,Insumos!$A$2:$C$67,2) -> QUESO TAJADO
A45: =VLOOKUP(B45,Productos!$A$2:$D$84,4,0) -> 3000 | B45: 44 | C45: SPEED | E45: =D45*A45 -> 0 | F45: JUGO HIT 1.5 | J45: 11 | K45: HAMB. SENCILLA | L45: I059 | M45: 30 | N45: =VLOOKUP(L45,Insumos!$A$2:$C$67,2) -> TOCINETA
A46: =VLOOKUP(B46,Productos!$A$2:$D$84,4,0) -> 9000 | B46: 45 | C46: MALTA | E46: =D46*A46 -> 0 | F46: PATACONA HAM | J46: 12 | K46: HAMB. POLLO | L46: I012 | M46: 1 | N46: =VLOOKUP(L46,Insumos!$A$2:$C$67,2) -> PAN HAMBURGUESA
A47: =VLOOKUP(B47,Productos!$A$2:$D$84,4,0) -> 5500 | B47: 46 | C47: CORONITA | E47: =D47*A47 -> 0 | F47: COLA Y POLA LATA | J47: 12 | K47: HAMB. POLLO | L47: I014 | M47: 1 | N47: =VLOOKUP(L47,Insumos!$A$2:$C$67,2) -> POLLO HAMBURGUESA
A48: =VLOOKUP(B48,Productos!$A$2:$D$84,4,0) -> 3500 | B48: 47 | C48: BRETAÑA | E48: =D48*A48 -> 0 | F48: H2O | J48: 12 | K48: HAMB. POLLO | L48: I051 | M48: 25 | N48: =VLOOKUP(L48,Insumos!$A$2:$C$67,2) -> QUESO TAJADO
A49: =VLOOKUP(B49,Productos!$A$2:$D$84,4,0) -> 11000 | B49: 48 | C49: SALCHIPAPA MINI | E49: =D49*A49 -> 0 | F49: PULPA FRUTA | J49: 12 | K49: HAMB. POLLO | L49: I059 | M49: 30 | N49: =VLOOKUP(L49,Insumos!$A$2:$C$67,2) -> TOCINETA
... A51: =VLOOKUP(B51,Productos!$A$2:$D$84,4,0) -> 14000 | B51: 50 | C51: COCA COLA 3L | E51: =D51*A51 -> 0 | F51: LOMO DE CERDO | J51: 13 | K51: HAMB. DOBLE CARNE | L51: I013 | M51: 2 | N51: =VLOOKUP(L51,Insumos!$A$2:$C$67,2) -> CARNE HAMBURGUESA
A52: =VLOOKUP(B52,Productos!$A$2:$D$84,4,0) -> 5000 | B52: 51 | C52: HUEVOS CODORNIZ | E52: =D52*A52 -> 0 | F52: PAPA RIPIO | G52: =(D8*30) -> 30 | J52: 13 | K52: HAMB. DOBLE CARNE | L52: I051 | M52: 50 | N52: =VLOOKUP(L52,Insumos!$A$2:$C$67,2) -> QUESO TAJADO
...

Sheet Ventas
A1: Fecha | B1: Hora | C1: Código_Producto | D1: Producto | E1: Cantidad | F1: Precio_Unitario | G1: Total | H1: Registrado_Por | I1: Estado | J1: Tipo_Pedido | K1: ID_Pedido | L1: Observacion

Sheet Recetas
A1: Codigo_Producto | B1: Producto | C1: Codigo_Insumo | D1: Cantidad | E1: Insumo
A2: 2 | B2: PIZZA HAWALLANA | C2: I002 | D2: 14 | E2: =VLOOKUP(C2,Insumos!$A$2:$C$67,2) -> JAMON
A3: 2 | B3: PIZZA HAWALLANA | C3: I003 | D3: 80 | E3: =VLOOKUP(C3,Insumos!$A$2:$C$67,2) -> QUESO PIZZA
A4: 2 | B4: PIZZA HAWALLANA | C4: I058 | D4: 1 | E4: =VLOOKUP(C4,Insumos!$A$2:$C$67,2) -> MASAS HECHAS
A5: 3 | B5: PIZZA CHAMPIÑONES | C5: I002 | D5: 14 | E5: =VLOOKUP(C5,Insumos!$A$2:$C$67,2) -> JAMON
A6: 3 | B6: PIZZA CHAMPIÑONES | C6: I003 | D6: 80 | E6: =VLOOKUP(C6,Insumos!$A$2:$C$67,2) -> QUESO PIZZA
A7: 3 | B7: PIZZA CHAMPIÑONES | C7: I058 | D7: 1 | E7: =VLOOKUP(C7,Insumos!$A$2:$C$67,2) -> MASAS HECHAS
A8: 3 | B8: PIZZA CHAMPIÑONES | C8: I006 | D8: 40 | E8: =VLOOKUP(C8,Insumos!$A$2:$C$67,2) -> POLLO PIZZA
A9: 3 | B9: PIZZA CHAMPIÑONES | C9: I004 | D9: 31 | E9: CHAMPIÑONES
A10: 4 | B10: PIZZA CARNES | C10: I002 | D10: 28 | E10: =VLOOKUP(C10,Insumos!$A$2:$C$67,2) -> JAMON
A11: 4 | B11: PIZZA CARNES | C11: I003 | D11: 80 | E11: =VLOOKUP(C11,Insumos!$A$2:$C$67,2) -> QUESO PIZZA
A12: 4 | B12: PIZZA CARNES | C12: I005 | D12: 31 | E12: =VLOOKUP(C12,Insumos!$A$2:$C$67,2) -> SALCHICHA IDEAL
A13: 4 | B13: PIZZA CARNES | C13: I006 | D13: 40 | E13: =VLOOKUP(C13,Insumos!$A$2:$C$67,2) -> POLLO PIZZA
A14: 4 | B14: PIZZA CARNES | C14: I058 | D14: 1 | E14: =VLOOKUP(C14,Insumos!$A$2:$C$67,2) -> MASAS HECHAS
A15: 5 | B15: PIZZA MEXICANA | C15: I003 | D15: 80 | E15: =VLOOKUP(C15,Insumos!$A$2:$C$67,2) -> QUESO PIZZA
A16: 5 | B16: PIZZA MEXICANA | C16: I007 | D16: 63 | E16: =VLOOKUP(C16,Insumos!$A$2:$C$67,2) -> CARNE PIZZA
A17: 5 | B17: PIZZA MEXICANA | C17: I008 | D17: 0.25 | E17: =VLOOKUP(C17,Insumos!$A$2:$C$67,2) -> CHISS TREES
A18: 5 | B18: PIZZA MEXICANA | C18: I058 | D18: 1 | E18: =VLOOKUP(C18,Insumos!$A$2:$C$67,2) -> MASAS HECHAS
A19: 6 | B19: PIZZA RANCHERA | C19: I002 | D19: 14 | E19: =VLOOKUP(C19,Insumos!$A$2:$C$67,2) -> JAMON
A20: 6 | B20: PIZZA RANCHERA | C20: I003 | D20: 80 | E20: =VLOOKUP(C20,Insumos!$A$2:$C$67,2) -> QUESO PIZZA
A21: 6 | B21: PIZZA RANCHERA | C21: I009 | D21: 31 | E21: =VLOOKUP(C21,Insumos!$A$2:$C$67,2) -> MAZORCA
... A188: 99 | B188: DESECHABLE | C188: I067 | D188: 1 | E188: =VLOOKUP(C188,Insumos!$A$2:$C$67,2) -> DESECHABLE

Sheet Insumos
A1: Codigo_Insumo | B1: Insumo | C1: Unidad
A2: I001 | B2: DESMECHADA | C2: gramos
A3: I002 | B3: JAMON | C3: gramos
A4: I003 | B4: QUESO PIZZA | C4: gramos
A5: I004 | B5: CHAMPIÑONES | C5: gramos
A6: I005 | B6: SALCHICHA IDEAL | C6: gramos
A7: I006 | B7: POLLO PIZZA | C7: gramos
A8: I007 | B8: CARNE PIZZA | C8: gramos
A9: I008 | B9: CHISS TREES | C9: unidad
A10: I009 | B10: MAZORCA | C10: gramos
A11: I010 | B11: SALCHICHA RANCHERA | C11: gramos
A12: I011 | B12: SALCHICHON | C12: gramos
... A67: I067 | B67: DESECHABLE | C67: unidad

Sheet Productos
A1: Código | B1: Nombre | C1: Categoría | D1: Precio_Venta | E1: Activo
A2: 2 | B2: PIZZA HAWALLANA | C2: PIZZA | D2: 9000
A3: 3 | B3: PIZZA CHAMPIÑONES | C3: PIZZA | D3: 9000
A4: 4 | B4: PIZZA CARNES | C4: PIZZA | D4: 9000
A5: 5 | B5: PIZZA MEXICANA | C5: PIZZA | D5: 9000
A6: 6 | B6: PIZZA RANCHERA | C6: PIZZA | D6: 9000
A7: 7 | B7: PIZZA PERRO | C7: PIZZA | D7: 9000
A8: 8 | B8: PIZZA COLOMBIANA | C8: PIZZA | D8: 9000
A9: 9 | B9: PIZZA DE LA CASA | C9: PIZZA | D9: 9000
A10: 10 | B10: PIZZA PEPERONI | C10: PIZZA | D10: 9000
A11: 11 | B11: HAMB. SENCILLA | C11: HAMBURGUESA | D11: 14000
A12: 12 | B12: HAMB. POLLO | C12: HAMBURGUESA | D12: 16000
A13: 13 | B13: HAMB. DOBLE CARNE | C13: HAMBURGUESA | D13: 19000
... A84: 99 | B84: DESECHABLE | C84: ADICIONALES | D84: 1000

Sheet Inventario_Insumos
A1: Fecha | B1: Codigo_Insumo | C1: Insumo | D1: Habia_Ayer | E1: Ingreso | F1: Gasto | G1: Gasto_JC | H1: Debe_Haber | I1: Existe_Real | J1: Diferencia | K1: Estado
G2: =D2+E2-F2 -> 0 | I2: =H2-G2 -> 0
A3: 46207 | B3: I001 | C3: DESMECHADA | D3: 2705 | E3: 0 | F3: 800 | G3: 0 | H3: 1905 | I3: 2310 | J3: 405 | K3: SIN CONTEO
A4: 46207 | B4: I002 | C4: JAMON | D4: 2661 | E4: 2500 | F4: 1906 | G4: 0 | H4: 3255 | I4: 2601 | J4: -654 | K4: SIN CONTEO
A5: 46207 | B5: I003 | C5: QUESO PIZZA | D5: 7430 | E5: 15000 | F5: 9960 | G5: 0 | H5: 12470 | I5: 11800 | J5: -670 | K5: SIN CONTEO
A6: 46207 | B6: I004 | C6: CHAMPIÑONES | D6: 1780 | E6: 0 | F6: 0 | G6: 0 | H6: 1780 | I6: 1318 | J6: -462 | K6: SIN CONTEO
A7: 46207 | B7: I005 | C7: SALCHICHA IDEAL | D7: 79910 | E7: 2440 | F7: 837 | G7: 0 | H7: 81513 | I7: 175375 | J7: 93862 | K7: SIN CONTEO
A8: 46207 | B8: I006 | C8: POLLO PIZZA | D8: 3215 | E8: 0 | F8: 600 | G8: 0 | H8: 2615 | I8: 2350 | J8: -265 | K8: SIN CONTEO
A9: 46207 | B9: I007 | C9: CARNE PIZZA | D9: 5870 | E9: 0 | F9: 252 | G9: 0 | H9: 5618 | I9: 5485 | J9: -133 | K9: SIN CONTEO
A10: 46207 | B10: I008 | C10: CHISS TREES | D10: 0 | E10: 0 | F10: 1 | G10: 0 | H10: -1 | I10: 249 | J10: 250 | K10: SIN CONTEO
A11: 46207 | B11: I009 | C11: MAZORCA | D11: 8480 | E11: 0 | F11: 1724 | G11: 0 | H11: 6756 | I11: 5760 | J11: -996 | K11: SIN CONTEO
A12: 46207 | B12: I010 | C12: SALCHICHA RANCHERA | D12: 1740 | E12: 1840 | F12: 744 | G12: 0 | H12: 2836 | I12: 3195 | J12: 359 | K12: SIN CONTEO
A13: 46207 | B13: I011 | C13: SALCHICHON | D13: 145 | E13: 0 | F13: 40 | G13: 0 | H13: 105 | I13: 0 | J13: -105 | K13: SIN CONTEO
A14: 46207 | B14: I012 | C14: PAN HAMBURGUESA | D14: 32 | E14: 60 | F14: 18 | G14: 0 | H14: 74 | I14: 66 | J14: -8 | K14: SIN CONTEO
... A68: 46207 | B68: I067 | C68: DESECHABLE | D68: 0 | E68: 0 | F68: 32 | G68: 0 | H68: -32 | I68: 0 | J68: 32 | K68: SIN CONTEO
